2025-09-21 01:24:01 [INFO] app.main:19 - Application startup initiated
2025-09-21 01:24:01 [INFO] app.main:23 - Database tables created successfully
2025-09-21 01:24:01 [INFO] app.main:28 - Application startup completed
2025-09-21 01:24:01 [INFO] httpx:1025 - HTTP Request: POST http://testserver/api/v1/categories/ "HTTP/1.1 201 Created"
2025-09-21 01:24:01 [INFO] httpx:1025 - HTTP Request: DELETE http://testserver/api/v1/categories/1 "HTTP/1.1 200 OK"
2025-09-21 01:24:01 [ERROR] tests.integration.conftest:41 - Error in override_get_db
Traceback (most recent call last):
  File "/home/runner/work/interview/interview/tests/integration/conftest.py", line 39, in override_get_db
    yield db
  File "/home/runner/work/interview/interview/.venv/lib/python3.13/site-packages/fastapi/concurrency.py", line 27, in contextmanager_in_threadpool
    yield await run_in_threadpool(cm.__enter__)
  File "/home/runner/work/interview/interview/.venv/lib/python3.13/site-packages/fastapi/routing.py", line 302, in app
    raw_response = await run_endpoint_function(
                   ^^^^^^^^^^^^^^^^^^^^^^^^^^^^
    ...<3 lines>...
    )
    ^
  File "/home/runner/work/interview/interview/.venv/lib/python3.13/site-packages/fastapi/routing.py", line 215, in run_endpoint_function
    return await run_in_threadpool(dependant.call, **values)
           ^^^^^^^^^^^^^^^^^^^^^^^^^^^^^^^^^^^^^^^^^^^^^^^^^
  File "/home/runner/work/interview/interview/.venv/lib/python3.13/site-packages/starlette/concurrency.py", line 38, in run_in_threadpool
    return await anyio.to_thread.run_sync(func)
           ^^^^^^^^^^^^^^^^^^^^^^^^^^^^^^^^^^^^
  File "/home/runner/work/interview/interview/.venv/lib/python3.13/site-packages/anyio/to_thread.py", line 56, in run_sync
    return await get_async_backend().run_sync_in_worker_thread(
           ^^^^^^^^^^^^^^^^^^^^^^^^^^^^^^^^^^^^^^^^^^^^^^^^^^^^
        func, args, abandon_on_cancel=abandon_on_cancel, limiter=limiter
        ^^^^^^^^^^^^^^^^^^^^^^^^^^^^^^^^^^^^^^^^^^^^^^^^^^^^^^^^^^^^^^^^
    )
    ^
  File "/home/runner/work/interview/interview/.venv/lib/python3.13/site-packages/anyio/_backends/_asyncio.py", line 2476, in run_sync_in_worker_thread
    return await future
           ^^^^^^^^^^^^
  File "/home/runner/work/interview/interview/.venv/lib/python3.13/site-packages/anyio/_backends/_asyncio.py", line 967, in run
    result = context.run(func, *args)
  File "/home/runner/work/interview/interview/backend/app/api/v1/endpoints/categories.py", line 28, in read_category
    raise HTTPException(status_code=404, detail="Category not found")
fastapi.exceptions.HTTPException: 404: Category not found
2025-09-21 01:24:01 [INFO] httpx:1025 - HTTP Request: GET http://testserver/api/v1/categories/1 "HTTP/1.1 404 Not Found"
2025-09-21 01:24:01 [INFO] app.main:32 - Application shutdown initiated
2025-09-21 01:24:01 [INFO] app.main:34 - Application shutdown completed
